Traceback (most recent call last):
  File "/home/sang/automated_image_processing/automated_image_processing/automated_image_processing/back-end/oop/test.py", line 10, in <module>
    objects = clothesDetector.localize_objects(image)
  File "/home/sang/automated_image_processing/automated_image_processing/automated_image_processing/back-end/oop/temp.py", line 302, in localize_objects
    objects = client.object_localization(
  File "/home/sang/.conda/envs/autoImage/lib/python3.10/site-packages/google/cloud/vision_helpers/decorators.py", line 112, in inner
    response = self.annotate_image(
  File "/home/sang/.conda/envs/autoImage/lib/python3.10/site-packages/google/cloud/vision_helpers/__init__.py", line 76, in annotate_image
    r = self.batch_annotate_images(
  File "/home/sang/.conda/envs/autoImage/lib/python3.10/site-packages/google/cloud/vision_v1/services/image_annotator/client.py", line 567, in batch_annotate_images
    response = rpc(
  File "/home/sang/.conda/envs/autoImage/lib/python3.10/site-packages/google/api_core/gapic_v1/method.py", line 113, in __call__
    return wrapped_func(*args, **kwargs)
  File "/home/sang/.conda/envs/autoImage/lib/python3.10/site-packages/google/api_core/grpc_helpers.py", line 74, in error_remapped_callable
    raise exceptions.from_grpc_error(exc) from exc
google.api_core.exceptions.Unauthenticated: 401 Request had invalid authentication credentials. Expected OAuth 2 access token, login cookie or other valid authentication credential. See https://developers.google.com/identity/sign-in/web/devconsole-project. [reason: "ACCESS_TOKEN_EXPIRED"
domain: "googleapis.com"
metadata {
  key: "service"
  value: "vision.googleapis.com"
}
metadata {
  key: "method"
  value: "google.cloud.vision.v1.ImageAnnotator.BatchAnnotateImages"
}
]